<?xml version="1.0" encoding="utf-8"?>
<!--
An order of joints (25 DoFs)
The name of joints can be seen in a below specification.
https://www.shadowrobot.com/wp-content/uploads/shadow_dexterous_hand_technical_specification_E_20190221.pdf
0 : robot0:slide
1 : robot0:WRJ1
2 : robot0:WRJ0
3 : robot0:FFJ3
4 : robot0:FFJ2
5 : robot0:FFJ1
6 : robot0:FFJ0
7 : robot0:MFJ3
8 : robot0:MFJ2
9 : robot0:MFJ1
10: robot0:MFJ0
11: robot0:RFJ3
12: robot0:RFJ2
13: robot0:RFJ1
14: robot0:RFJ0
15: robot0:LFJ4
16: robot0:LFJ3
17: robot0:LFJ2
18: robot0:LFJ1
19: robot0:LFJ0
20: robot0:THJ4
21: robot0:THJ3
22: robot0:THJ2
23: robot0:THJ1
24: robot0:THJ0
-->
<mujoco>
    <compiler angle="radian" coordinate="local" meshdir="../stls" texturedir="../textures"></compiler>
    <option timestep="0.002" iterations="20" apirate="200">
<!--         gravity="0 0 0" 重力のoptionを追加。重力０に。-->
        <flag warmstart="enable"></flag>
    </option>

    <worldbody>

<!--          箱ひげ図の誤差を計算したはさみモデル  ShadowHandLite用  はさみの形変更, 刃の重なりを無くす-->
<!--         上下反転させたはさみのモデル-->
        <body name="scissors_part0" pos="1.07 0.892 0.4">
            <geom name="scissors" type="sphere" size="0.001 0.001 0.001" condim="4" group="2"
                  contype="0" conaffinity="0" rgba="0.9 0.9 0.1 1"></geom>
            <site name="scissors:center" pos="0 0 0" rgba="1 0 0 0" size="0.01 0.01 0.01"></site>
            <joint name="scissors:joint" type="free" damping="0.01"></joint>
            <body name="scissors_part1_mirror" pos="0 0 0">
                <joint name="scissors_hinge_1:joint" type="hinge" pos="0 0 0" axis="0 0 1" limited="true" range="-0.52358 0.52358" damping="0.1" armature="0.01"></joint>
                <geom name="scissors_part1_mirror" type="box" friction="1.5 0.005 0.0001" size="0.1 0.008 0.004"></geom>

                <body name="scissors_part2_mirror" pos="0 0.024 0">
                    <geom name="scissors_part2_mirror" type="box" friction="1.5 0.005 0.0001" size="0.02 0.008 0.004" euler="0 0 -1.57075"></geom>
                    <body name="scissors_part3_mirror" pos="-0.045 0.027 0">
                        <geom name="scissors_part3_mirror" type="box" friction="1.5 0.005 0.0001" size="0.053 0.008 0.004" euler="0 0 0"></geom>
                        <body name="scissors_part4_mirror" pos="-0.058 -0.025 0">
                            <geom name="scissors_part4_mirror" type="box" friction="1.5 0.005 0.0001" size="0.034 0.008 0.004" euler="0 0 -1.57075"></geom>
                            <body name="scissors_part5_mirror" pos="0.045 -0.018 0">
                                <geom name="scissors_part5_mirror" type="box" friction="1.5 0.005 0.0001" size="0.05 0.008 0.004" euler="0 0 0"></geom>
                            </body>
                        </body>
                    </body>
                </body>
            </body>
        </body>


    </worldbody>

</mujoco>
